Workbook

Sheet Purchase Contracts
A1: Purchase Contract # | B1: Customer | C1: Commodity | D1: DLV Location | E1: DLV Period | F1: Futures Code | G1: Fut Px | H1: Basis | I1: Cash Px | J1: Bushels | K1: Delivered | L1: Remaining | M1: Fill %
A2: C26001 | B2: Kuhlman Farms | C2: Corn | D2: Houston | E2: Feb-26 | F2: CH26 | G2: 4.87 | H2: =IF($C2="Corn",_xlfn.XLOOKUP($E2,$D$22:$D$29,$E$22:$E$29),_xlfn.XLOOKUP($E2,$D$22:$D$29,$F$22:$F$29)) -> -0.18 | I2: =G2+H2 -> 4.69 | J2: 5000 | K2: =SUMIFS('Inbound Scale Tickets'!$S:$S,'Inbound Scale Tickets'!$B:$B,A2) -> 1682 | L2: =J2-K2 -> 3318 | M2: =IF(J2=0,0,K2/J2) -> 0.3364
A3: C26002 | B3: Schardt Farms | C3: Corn | D3: Houston | E3: Feb-26 | F3: CH26 | G3: 4.87 | H3: =IF($C3="Corn",_xlfn.XLOOKUP($E3,$D$22:$D$29,$E$22:$E$29),_xlfn.XLOOKUP($E3,$D$22:$D$29,$F$22:$F$29)) -> -0.18 | I3: =G3+H3 -> 4.69 | J3: 10000 | K3: =SUMIFS('Inbound Scale Tickets'!$S:$S,'Inbound Scale Tickets'!$B:$B,A3) -> 849 | L3: =J3-K3 -> 9151 | M3: =IF(J3=0,0,K3/J3) -> 0.0849
A4: C26003 | B4: Meyer Farms | C4: Corn | D4: Houston | E4: Mar-26 | F4: CH26 | G4: 4.92 | H4: =IF($C4="Corn",_xlfn.XLOOKUP($E4,$D$22:$D$29,$E$22:$E$29),_xlfn.XLOOKUP($E4,$D$22:$D$29,$F$22:$F$29)) -> -0.24 | I4: =G4+H4 -> 4.68 | J4: 15000 | K4: =SUMIFS('Inbound Scale Tickets'!$S:$S,'Inbound Scale Tickets'!$B:$B,A4) -> 3378 | L4: =J4-K4 -> 11622 | M4: =IF(J4=0,0,K4/J4) -> 0.2252
A5: C26004 | B5: Walter Grain | C5: Corn | D5: Houston | E5: Jun-26 | F5: CN26 | G5: 5.08 | H5: =IF($C5="Corn",_xlfn.XLOOKUP($E5,$D$22:$D$29,$E$22:$E$29),_xlfn.XLOOKUP($E5,$D$22:$D$29,$F$22:$F$29)) -> -0.22 | I5: =G5+H5 -> 4.86 | J5: 25000 | K5: =SUMIFS('Inbound Scale Tickets'!$S:$S,'Inbound Scale Tickets'!$B:$B,A5) -> 0 | L5: =J5-K5 -> 25000 | M5: =IF(J5=0,0,K5/J5) -> 0
A6: C26005 | B6: Hoffman Farms | C6: Corn | D6: Houston | E6: Jul-26 | F6: CN26 | G6: 5.12 | H6: =IF($C6="Corn",_xlfn.XLOOKUP($E6,$D$22:$D$29,$E$22:$E$29),_xlfn.XLOOKUP($E6,$D$22:$D$29,$F$22:$F$29)) -> -0.28 | I6: =G6+H6 -> 4.84 | J6: 10000 | K6: =SUMIFS('Inbound Scale Tickets'!$S:$S,'Inbound Scale Tickets'!$B:$B,A6) -> 832 | L6: =J6-K6 -> 9168 | M6: =IF(J6=0,0,K6/J6) -> 0.0832
A7: C26006 | B7: Brenneman Farms | C7: Corn | D7: Houston | E7: Sep-26 | F7: CU26 | G7: 5.01 | H7: =IF($C7="Corn",_xlfn.XLOOKUP($E7,$D$22:$D$29,$E$22:$E$29),_xlfn.XLOOKUP($E7,$D$22:$D$29,$F$22:$F$29)) -> -0.33 | I7: =G7+H7 -> 4.68 | J7: 12000 | K7: =SUMIFS('Inbound Scale Tickets'!$S:$S,'Inbound Scale Tickets'!$B:$B,A7) -> 0 | L7: =J7-K7 -> 12000 | M7: =IF(J7=0,0,K7/J7) -> 0
A8: C26007 | B8: Ridgeview Ag | C8: Corn | D8: Houston | E8: Oct-Nov 26 | F8: CZ26 | G8: 4.78 | H8: =IF($C8="Corn",_xlfn.XLOOKUP($E8,$D$22:$D$29,$E$22:$E$29),_xlfn.XLOOKUP($E8,$D$22:$D$29,$F$22:$F$29)) -> -0.42 | I8: =G8+H8 -> 4.36 | J8: 30000 | K8: =SUMIFS('Inbound Scale Tickets'!$S:$S,'Inbound Scale Tickets'!$B:$B,A8) -> 6114 | L8: =J8-K8 -> 23886 | M8: =IF(J8=0,0,K8/J8) -> 0.2038
A9: C26008 | B9: Triple Creek Farms | C9: Corn | D9: Houston | E9: Oct-Nov 26 | F9: CZ26 | G9: 4.78 | H9: =IF($C9="Corn",_xlfn.XLOOKUP($E9,$D$22:$D$29,$E$22:$E$29),_xlfn.XLOOKUP($E9,$D$22:$D$29,$F$22:$F$29)) -> -0.42 | I9: =G9+H9 -> 4.36 | J9: 20000 | K9: =SUMIFS('Inbound Scale Tickets'!$S:$S,'Inbound Scale Tickets'!$B:$B,A9) -> 3477 | L9: =J9-K9 -> 16523 | M9: =IF(J9=0,0,K9/J9) -> 0.17385
A10: S26001 | B10: Kramer Farms | C10: Soybeans | D10: Houston | E10: Aug-26 | F10: SQ26 | G10: 10.58 | H10: =IF($C10="Corn",_xlfn.XLOOKUP($E10,$D$22:$D$29,$E$22:$E$29),_xlfn.XLOOKUP($E10,$D$22:$D$29,$F$22:$F$29)) -> -0.4 | I10: =G10+H10 -> 10.18 | J10: 4000 | K10: =SUMIFS('Inbound Scale Tickets'!$S:$S,'Inbound Scale Tickets'!$B:$B,A10) -> 0 | L10: =J10-K10 -> 4000 | M10: =IF(J10=0,0,K10/J10) -> 0
A11: S26002 | B11: Johnson Farms | C11: Soybeans | D11: Houston | E11: Aug-26 | F11: SU26 | G11: 10.74 | H11: =IF($C11="Corn",_xlfn.XLOOKUP($E11,$D$22:$D$29,$E$22:$E$29),_xlfn.XLOOKUP($E11,$D$22:$D$29,$F$22:$F$29)) -> -0.4 | I11: =G11+H11 -> 10.34 | J11: 2500 | K11: =SUMIFS('Inbound Scale Tickets'!$S:$S,'Inbound Scale Tickets'!$B:$B,A11) -> 830 | L11: =J11-K11 -> 1670 | M11: =IF(J11=0,0,K11/J11) -> 0.332
A12: S26003 | B12: Miller Farms | C12: Soybeans | D12: Houston | E12: Oct-Nov 26 | F12: SX26 | G12: 10.95 | H12: =IF($C12="Corn",_xlfn.XLOOKUP($E12,$D$22:$D$29,$E$22:$E$29),_xlfn.XLOOKUP($E12,$D$22:$D$29,$F$22:$F$29)) -> -0.55 | I12: =G12+H12 -> 10.4 | J12: 8000 | K12: =SUMIFS('Inbound Scale Tickets'!$S:$S,'Inbound Scale Tickets'!$B:$B,A12) -> 3288 | L12: =J12-K12 -> 4712 | M12: =IF(J12=0,0,K12/J12) -> 0.411
A13: S26004 | B13: Baughman Farms | C13: Soybeans | D13: Houston | E13: Oct-Nov 26 | F13: SX26 | G13: 10.95 | H13: =IF($C13="Corn",_xlfn.XLOOKUP($E13,$D$22:$D$29,$E$22:$E$29),_xlfn.XLOOKUP($E13,$D$22:$D$29,$F$22:$F$29)) -> -0.55 | I13: =G13+H13 -> 10.4 | J13: 5000 | K13: =SUMIFS('Inbound Scale Tickets'!$S:$S,'Inbound Scale Tickets'!$B:$B,A13) -> 0 | L13: =J13-K13 -> 5000 | M13: =IF(J13=0,0,K13/J13) -> 0
... A15: S26006 | B15: Four Star Farms | C15: Soybeans | D15: Houston | E15: Oct-Nov 26 | F15: SX26 | G15: 10.95 | H15: =IF($C15="Corn",_xlfn.XLOOKUP($E15,$D$22:$D$29,$E$22:$E$29),_xlfn.XLOOKUP($E15,$D$22:$D$29,$F$22:$F$29)) -> -0.55 | I15: =G15+H15 -> 10.4 | J15: 10000 | K15: =SUMIFS('Inbound Scale Tickets'!$S:$S,'Inbound Scale Tickets'!$B:$B,A15) -> 1630 | L15: =J15-K15 -> 8370 | M15: =IF(J15=0,0,K15/J15) -> 0.163
A16: S26007 | B16: Northfield Farms | C16: Soybeans | D16: Houston | E16: Nov-26 | F16: SX26 | G16: 11.05 | H16: =IF($C16="Corn",_xlfn.XLOOKUP($E16,$D$22:$D$29,$E$22:$E$29),_xlfn.XLOOKUP($E16,$D$22:$D$29,$F$22:$F$29)) -> -0.42 | I16: =G16+H16 -> 10.63 | J16: 6000 | K16: =SUMIFS('Inbound Scale Tickets'!$S:$S,'Inbound Scale Tickets'!$B:$B,A16) -> 0 | L16: =J16-K16 -> 6000 | M16: 0.07
D19: Posted Basis
D21: DLV Period | E21: Corn Basis | F21: Soybean Basis
D22: Feb-26 | E22: -0.18 | F22: —
D23: Mar-26 | E23: -0.24 | F23: —
D24: Jun-26 | E24: -0.22 | F24: —
D25: Jul-26 | E25: -0.28 | F25: —
D26: Aug-26 | E26: — | F26: -0.4
D27: Sep-26 | E27: -0.33 | F27: —
D28: Nov-26 | E28: — | F28: -0.42
D29: Oct-Nov 26 | E29: -0.42 | F29: -0.55

Sheet Inbound Scale Tickets
A1: Ticket # | B1: Contract # | C1: Customer | D1: Commodity | E1: DLV Location | F1: Driver | G1: License Plate | H1: DLV Date | I1: Time In | J1: Time Out | K1: Gross Wt | L1: Tare Wt | M1: Net Wt | N1: TW | O1: Mt % | P1: Damage % | Q1: FM % | R1: Dockage ($/bu) | S1: Net Bu
A2: T1001 | B2: C26007 | C2: Ridgeview Ag | D2: Corn | E2: Houston | F2: Jake Miller | G2: TX-4821 | H2: 46267 | I2: 0.3 | J2: 0.30902778 | K2: 80240 | L2: 32180 | M2: =K2-L2 -> 48060 | N2: 56.8 | O2: 14.7 | P2: 1.8 | Q2: 0.8 | R2: =IF($D2="Corn", SUMIFS('Discount Schedules'!$I$6:$I$22,'Discount Schedules'!$F$6:$F$22,"Moisture",'Discount Schedules'!$G$6:$G$22,"<="&$O2,'Discount Schedules'!$H$6:$H$22,">="&$O2) +SUMIFS('Discount Schedules'!$I$6:$I$22,'Discount Schedules'!$F$6:$F$22,"Test Weight",'Discount Schedules'!$G$6:$G$22,"<="&$N2,'Discount Schedules'!$H$6:$H$22,">="&$N2) +SUMIFS('Discount Schedules'!$I$6:$I$22,'Discount Schedules'!$F$6:$F$22,"Damage",'Discount Schedules'!$G$6:$G$22,"<="&$P2,'Discount Schedules'!$H$6:$H$22,">="&$P2) +SUMIFS('Discount Schedules'!$I$6:$I$22,'Discount Schedules'!$F$6:$F$22,"FM",'Discount Schedules'!$G$6:$G$22,"<="&$Q2,'Discount Schedules'!$H$6:$H$22,">="&$Q2), IF($D2="Soybeans", SUMIFS('Discount Schedules'!$N$6:$N$22,'Discount Schedules'!$K$6:$K$22,"Moisture",'Discount Schedules'!$L$6:$L$22,"<="&$O2,'Discount Schedules'!$M$6:$M$22,">="&$O2) +SUMIFS('Discount Schedules'!$N$6:$N$22,'Discount Schedules'!$K$6:$K$22,"Test Weight",'Discount Schedules'!$L$6:$L$22,"<="&$N2,'Discount Schedules'!$M$6:$M$22,">="&$N2) +SUMIFS('Discount Schedules'!$N$6:$N$22,'Discount Schedules'!$K$6:$K$22,"Damage",'Discount Schedules'!$L$6:$L$22,"<="&$P2,'Discount Schedules'!$M$6:$M$22,">="&$P2) +SUMIFS('Discount Schedules'!$N$6:$N$22,'Discount Schedules'!$K$6:$K$22,"FM",'Discount Schedules'!$L$6:$L$22,"<="&$Q2,'Discount Schedules'!$M$6:$M$22,">="&$Q2),"")) -> 0 | S2: =IF(D2="Corn",ROUND(M2/56,0),ROUND(M2/60,0)) -> 858
A3: T1002 | B3: C26003 | C3: Meyer Farms | D3: Corn | E3: Houston | F3: Travis Johnson | G3: TX-6154 | H3: 46267 | I3: 0.31111111 | J3: 0.32013889 | K3: 78620 | L3: 31540 | M3: =K3-L3 -> 47080 | N3: 56.1 | O3: 15.2 | P3: 2.2 | Q3: 1.2 | R3: =IF($D3="Corn", SUMIFS('Discount Schedules'!$I$6:$I$22,'Discount Schedules'!$F$6:$F$22,"Moisture",'Discount Schedules'!$G$6:$G$22,"<="&$O3,'Discount Schedules'!$H$6:$H$22,">="&$O3) +SUMIFS('Discount Schedules'!$I$6:$I$22,'Discount Schedules'!$F$6:$F$22,"Test Weight",'Discount Schedules'!$G$6:$G$22,"<="&$N3,'Discount Schedules'!$H$6:$H$22,">="&$N3) +SUMIFS('Discount Schedules'!$I$6:$I$22,'Discount Schedules'!$F$6:$F$22,"Damage",'Discount Schedules'!$G$6:$G$22,"<="&$P3,'Discount Schedules'!$H$6:$H$22,">="&$P3) +SUMIFS('Discount Schedules'!$I$6:$I$22,'Discount Schedules'!$F$6:$F$22,"FM",'Discount Schedules'!$G$6:$G$22,"<="&$Q3,'Discount Schedules'!$H$6:$H$22,">="&$Q3), IF($D3="Soybeans", SUMIFS('Discount Schedules'!$N$6:$N$22,'Discount Schedules'!$K$6:$K$22,"Moisture",'Discount Schedules'!$L$6:$L$22,"<="&$O3,'Discount Schedules'!$M$6:$M$22,">="&$O3) +SUMIFS('Discount Schedules'!$N$6:$N$22,'Discount Schedules'!$K$6:$K$22,"Test Weight",'Discount Schedules'!$L$6:$L$22,"<="&$N3,'Discount Schedules'!$M$6:$M$22,">="&$N3) +SUMIFS('Discount Schedules'!$N$6:$N$22,'Discount Schedules'!$K$6:$K$22,"Damage",'Discount Schedules'!$L$6:$L$22,"<="&$P3,'Discount Schedules'!$M$6:$M$22,">="&$P3) +SUMIFS('Discount Schedules'!$N$6:$N$22,'Discount Schedules'!$K$6:$K$22,"FM",'Discount Schedules'!$L$6:$L$22,"<="&$Q3,'Discount Schedules'!$M$6:$M$22,">="&$Q3),"")) -> 0.04 | S3: =IF(D3="Corn",ROUND(M3/56,0),ROUND(M3/60,0)) -> 841
A4: T1003 | B4: S26003 | C4: Miller Farms | D4: Soybeans | E4: Houston | F4: Cody Smith | G4: TX-7932 | H4: 46267 | I4: 0.32013889 | J4: 0.33055556 | K4: 79280 | L4: 30220 | M4: =K4-L4 -> 49060 | N4: 58.4 | O4: 12.9 | P4: 1.5 | Q4: 0.7 | R4: =IF($D4="Corn", SUMIFS('Discount Schedules'!$I$6:$I$22,'Discount Schedules'!$F$6:$F$22,"Moisture",'Discount Schedules'!$G$6:$G$22,"<="&$O4,'Discount Schedules'!$H$6:$H$22,">="&$O4) +SUMIFS('Discount Schedules'!$I$6:$I$22,'Discount Schedules'!$F$6:$F$22,"Test Weight",'Discount Schedules'!$G$6:$G$22,"<="&$N4,'Discount Schedules'!$H$6:$H$22,">="&$N4) +SUMIFS('Discount Schedules'!$I$6:$I$22,'Discount Schedules'!$F$6:$F$22,"Damage",'Discount Schedules'!$G$6:$G$22,"<="&$P4,'Discount Schedules'!$H$6:$H$22,">="&$P4) +SUMIFS('Discount Schedules'!$I$6:$I$22,'Discount Schedules'!$F$6:$F$22,"FM",'Discount Schedules'!$G$6:$G$22,"<="&$Q4,'Discount Schedules'!$H$6:$H$22,">="&$Q4), IF($D4="Soybeans", SUMIFS('Discount Schedules'!$N$6:$N$22,'Discount Schedules'!$K$6:$K$22,"Moisture",'Discount Schedules'!$L$6:$L$22,"<="&$O4,'Discount Schedules'!$M$6:$M$22,">="&$O4) +SUMIFS('Discount Schedules'!$N$6:$N$22,'Discount Schedules'!$K$6:$K$22,"Test Weight",'Discount Schedules'!$L$6:$L$22,"<="&$N4,'Discount Schedules'!$M$6:$M$22,">="&$N4) +SUMIFS('Discount Schedules'!$N$6:$N$22,'Discount Schedules'!$K$6:$K$22,"Damage",'Discount Schedules'!$L$6:$L$22,"<="&$P4,'Discount Schedules'!$M$6:$M$22,">="&$P4) +SUMIFS('Discount Schedules'!$N$6:$N$22,'Discount Schedules'!$K$6:$K$22,"FM",'Discount Schedules'!$L$6:$L$22,"<="&$Q4,'Discount Schedules'!$M$6:$M$22,">="&$Q4),"")) -> 0 | S4: =IF(D4="Corn",ROUND(M4/56,0),ROUND(M4/60,0)) -> 818
A5: T1004 | B5: C26007 | C5: Ridgeview Ag | D5: Corn | E5: Houston | F5: Jake Miller | G5: TX-4821 | H5: 46267 | I5: 0.33541667 | J5: 0.34652778 | K5: 80840 | L5: 32060 | M5: =K5-L5 -> 48780 | N5: 56.5 | O5: 14.4 | P5: 1.9 | Q5: 0.9 | R5: =IF($D5="Corn", SUMIFS('Discount Schedules'!$I$6:$I$22,'Discount Schedules'!$F$6:$F$22,"Moisture",'Discount Schedules'!$G$6:$G$22,"<="&$O5,'Discount Schedules'!$H$6:$H$22,">="&$O5) +SUMIFS('Discount Schedules'!$I$6:$I$22,'Discount Schedules'!$F$6:$F$22,"Test Weight",'Discount Schedules'!$G$6:$G$22,"<="&$N5,'Discount Schedules'!$H$6:$H$22,">="&$N5) +SUMIFS('Discount Schedules'!$I$6:$I$22,'Discount Schedules'!$F$6:$F$22,"Damage",'Discount Schedules'!$G$6:$G$22,"<="&$P5,'Discount Schedules'!$H$6:$H$22,">="&$P5) +SUMIFS('Discount Schedules'!$I$6:$I$22,'Discount Schedules'!$F$6:$F$22,"FM",'Discount Schedules'!$G$6:$G$22,"<="&$Q5,'Discount Schedules'!$H$6:$H$22,">="&$Q5), IF($D5="Soybeans", SUMIFS('Discount Schedules'!$N$6:$N$22,'Discount Schedules'!$K$6:$K$22,"Moisture",'Discount Schedules'!$L$6:$L$22,"<="&$O5,'Discount Schedules'!$M$6:$M$22,">="&$O5) +SUMIFS('Discount Schedules'!$N$6:$N$22,'Discount Schedules'!$K$6:$K$22,"Test Weight",'Discount Schedules'!$L$6:$L$22,"<="&$N5,'Discount Schedules'!$M$6:$M$22,">="&$N5) +SUMIFS('Discount Schedules'!$N$6:$N$22,'Discount Schedules'!$K$6:$K$22,"Damage",'Discount Schedules'!$L$6:$L$22,"<="&$P5,'Discount Schedules'!$M$6:$M$22,">="&$P5) +SUMIFS('Discount Schedules'!$N$6:$N$22,'Discount Schedules'!$K$6:$K$22,"FM",'Discount Schedules'!$L$6:$L$22,"<="&$Q5,'Discount Schedules'!$M$6:$M$22,">="&$Q5),"")) -> 0 | S5: =IF(D5="Corn",ROUND(M5/56,0),ROUND(M5/60,0)) -> 871
A6: T1005 | B6: C26001 | C6: Kuhlman Farms | D6: Corn | E6: Houston | F6: Ryan Davis | G6: TX-2207 | H6: 46267 | I6: 0.34513889 | J6: 0.35555556 | K6: 78120 | L6: 31040 | M6: =K6-L6 -> 47080 | N6: 55.8 | O6: 18.7 | P6: 54.2 | Q6: 1.1 | R6: =IF($D6="Corn", SUMIFS('Discount Schedules'!$I$6:$I$22,'Discount Schedules'!$F$6:$F$22,"Moisture",'Discount Schedules'!$G$6:$G$22,"<="&$O6,'Discount Schedules'!$H$6:$H$22,">="&$O6) +SUMIFS('Discount Schedules'!$I$6:$I$22,'Discount Schedules'!$F$6:$F$22,"Test Weight",'Discount Schedules'!$G$6:$G$22,"<="&$N6,'Discount Schedules'!$H$6:$H$22,">="&$N6) +SUMIFS('Discount Schedules'!$I$6:$I$22,'Discount Schedules'!$F$6:$F$22,"Damage",'Discount Schedules'!$G$6:$G$22,"<="&$P6,'Discount Schedules'!$H$6:$H$22,">="&$P6) +SUMIFS('Discount Schedules'!$I$6:$I$22,'Discount Schedules'!$F$6:$F$22,"FM",'Discount Schedules'!$G$6:$G$22,"<="&$Q6,'Discount Schedules'!$H$6:$H$22,">="&$Q6), IF($D6="Soybeans", SUMIFS('Discount Schedules'!$N$6:$N$22,'Discount Schedules'!$K$6:$K$22,"Moisture",'Discount Schedules'!$L$6:$L$22,"<="&$O6,'Discount Schedules'!$M$6:$M$22,">="&$O6) +SUMIFS('Discount Schedules'!$N$6:$N$22,'Discount Schedules'!$K$6:$K$22,"Test Weight",'Discount Schedules'!$L$6:$L$22,"<="&$N6,'Discount Schedules'!$M$6:$M$22,">="&$N6) +SUMIFS('Discount Schedules'!$N$6:$N$22,'Discount Schedules'!$K$6:$K$22,"Damage",'Discount Schedules'!$L$6:$L$22,"<="&$P6,'Discount Schedules'!$M$6:$M$22,">="&$P6) +SUMIFS('Discount Schedules'!$N$6:$N$22,'Discount Schedules'!$K$6:$K$22,"FM",'Discount Schedules'!$L$6:$L$22,"<="&$Q6,'Discount Schedules'!$M$6:$M$22,">="&$Q6),"")) -> 0.39 | S6: =IF(D6="Corn",ROUND(M6/56,0),ROUND(M6/60,0)) -> 841
A7: T1006 | B7: C26008 | C7: Triple Creek Farm | D7: Corn | E7: Houston | F7: Matt Wilson | G7: TX-5189 | H7: 46267 | I7: 0.35694444 | J7: 0.36805556 | K7: 80460 | L7: 31860 | M7: =K7-L7 -> 48600 | N7: 56.9 | O7: 14.8 | P7: 1.7 | Q7: 0.6 | R7: =IF($D7="Corn", SUMIFS('Discount Schedules'!$I$6:$I$22,'Discount Schedules'!$F$6:$F$22,"Moisture",'Discount Schedules'!$G$6:$G$22,"<="&$O7,'Discount Schedules'!$H$6:$H$22,">="&$O7) +SUMIFS('Discount Schedules'!$I$6:$I$22,'Discount Schedules'!$F$6:$F$22,"Test Weight",'Discount Schedules'!$G$6:$G$22,"<="&$N7,'Discount Schedules'!$H$6:$H$22,">="&$N7) +SUMIFS('Discount Schedules'!$I$6:$I$22,'Discount Schedules'!$F$6:$F$22,"Damage",'Discount Schedules'!$G$6:$G$22,"<="&$P7,'Discount Schedules'!$H$6:$H$22,">="&$P7) +SUMIFS('Discount Schedules'!$I$6:$I$22,'Discount Schedules'!$F$6:$F$22,"FM",'Discount Schedules'!$G$6:$G$22,"<="&$Q7,'Discount Schedules'!$H$6:$H$22,">="&$Q7), IF($D7="Soybeans", SUMIFS('Discount Schedules'!$N$6:$N$22,'Discount Schedules'!$K$6:$K$22,"Moisture",'Discount Schedules'!$L$6:$L$22,"<="&$O7,'Discount Schedules'!$M$6:$M$22,">="&$O7) +SUMIFS('Discount Schedules'!$N$6:$N$22,'Discount Schedules'!$K$6:$K$22,"Test Weight",'Discount Schedules'!$L$6:$L$22,"<="&$N7,'Discount Schedules'!$M$6:$M$22,">="&$N7) +SUMIFS('Discount Schedules'!$N$6:$N$22,'Discount Schedules'!$K$6:$K$22,"Damage",'Discount Schedules'!$L$6:$L$22,"<="&$P7,'Discount Schedules'!$M$6:$M$22,">="&$P7) +SUMIFS('Discount Schedules'!$N$6:$N$22,'Discount Schedules'!$K$6:$K$22,"FM",'Discount Schedules'!$L$6:$L$22,"<="&$Q7,'Discount Schedules'!$M$6:$M$22,">="&$Q7),"")) -> 0 | S7: =IF(D7="Corn",ROUND(M7/56,0),ROUND(M7/60,0)) -> 868
A8: T1007 | B8: S26005 | C8: Heritage Ag | D8: Soybeans | E8: Houston | F8: Cody Smith | G8: TX-7932 | H8: 46267 | I8: 0.36736111 | J8: 0.37986111 | K8: 79820 | L8: 30120 | M8: =K8-L8 -> 49700 | N8: 58.1 | O8: 13.2 | P8: 1.4 | Q8: 0.8 | R8: =IF($D8="Corn", SUMIFS('Discount Schedules'!$I$6:$I$22,'Discount Schedules'!$F$6:$F$22,"Moisture",'Discount Schedules'!$G$6:$G$22,"<="&$O8,'Discount Schedules'!$H$6:$H$22,">="&$O8) +SUMIFS('Discount Schedules'!$I$6:$I$22,'Discount Schedules'!$F$6:$F$22,"Test Weight",'Discount Schedules'!$G$6:$G$22,"<="&$N8,'Discount Schedules'!$H$6:$H$22,">="&$N8) +SUMIFS('Discount Schedules'!$I$6:$I$22,'Discount Schedules'!$F$6:$F$22,"Damage",'Discount Schedules'!$G$6:$G$22,"<="&$P8,'Discount Schedules'!$H$6:$H$22,">="&$P8) +SUMIFS('Discount Schedules'!$I$6:$I$22,'Discount Schedules'!$F$6:$F$22,"FM",'Discount Schedules'!$G$6:$G$22,"<="&$Q8,'Discount Schedules'!$H$6:$H$22,">="&$Q8), IF($D8="Soybeans", SUMIFS('Discount Schedules'!$N$6:$N$22,'Discount Schedules'!$K$6:$K$22,"Moisture",'Discount Schedules'!$L$6:$L$22,"<="&$O8,'Discount Schedules'!$M$6:$M$22,">="&$O8) +SUMIFS('Discount Schedules'!$N$6:$N$22,'Discount Schedules'!$K$6:$K$22,"Test Weight",'Discount Schedules'!$L$6:$L$22,"<="&$N8,'Discount Schedules'!$M$6:$M$22,">="&$N8) +SUMIFS('Discount Schedules'!$N$6:$N$22,'Discount Schedules'!$K$6:$K$22,"Damage",'Discount Schedules'!$L$6:$L$22,"<="&$P8,'Discount Schedules'!$M$6:$M$22,">="&$P8) +SUMIFS('Discount Schedules'!$N$6:$N$22,'Discount Schedules'!$K$6:$K$22,"FM",'Discount Schedules'!$L$6:$L$22,"<="&$Q8,'Discount Schedules'!$M$6:$M$22,">="&$Q8),"")) -> 0.01 | S8: =IF(D8="Corn",ROUND(M8/56,0),ROUND(M8/60,0)) -> 828
A9: T1008 | B9: C26003 | C9: Meyer Farms | D9: Corn | E9: Houston | F9: Travis Johnson | G9: TX-6154 | H9: 46267 | I9: 0.37638889 | J9: 0.3875 | K9: 79060 | L9: 31560 | M9: =K9-L9 -> 47500 | N9: 56 | O9: 15.4 | P9: 2.3 | Q9: 1.3 | R9: =IF($D9="Corn", SUMIFS('Discount Schedules'!$I$6:$I$22,'Discount Schedules'!$F$6:$F$22,"Moisture",'Discount Schedules'!$G$6:$G$22,"<="&$O9,'Discount Schedules'!$H$6:$H$22,">="&$O9) +SUMIFS('Discount Schedules'!$I$6:$I$22,'Discount Schedules'!$F$6:$F$22,"Test Weight",'Discount Schedules'!$G$6:$G$22,"<="&$N9,'Discount Schedules'!$H$6:$H$22,">="&$N9) +SUMIFS('Discount Schedules'!$I$6:$I$22,'Discount Schedules'!$F$6:$F$22,"Damage",'Discount Schedules'!$G$6:$G$22,"<="&$P9,'Discount Schedules'!$H$6:$H$22,">="&$P9) +SUMIFS('Discount Schedules'!$I$6:$I$22,'Discount Schedules'!$F$6:$F$22,"FM",'Discount Schedules'!$G$6:$G$22,"<="&$Q9,'Discount Schedules'!$H$6:$H$22,">="&$Q9), IF($D9="Soybeans", SUMIFS('Discount Schedules'!$N$6:$N$22,'Discount Schedules'!$K$6:$K$22,"Moisture",'Discount Schedules'!$L$6:$L$22,"<="&$O9,'Discount Schedules'!$M$6:$M$22,">="&$O9) +SUMIFS('Discount Schedules'!$N$6:$N$22,'Discount Schedules'!$K$6:$K$22,"Test Weight",'Discount Schedules'!$L$6:$L$22,"<="&$N9,'Discount Schedules'!$M$6:$M$22,">="&$N9) +SUMIFS('Discount Schedules'!$N$6:$N$22,'Discount Schedules'!$K$6:$K$22,"Damage",'Discount Schedules'!$L$6:$L$22,"<="&$P9,'Discount Schedules'!$M$6:$M$22,">="&$P9) +SUMIFS('Discount Schedules'!$N$6:$N$22,'Discount Schedules'!$K$6:$K$22,"FM",'Discount Schedules'!$L$6:$L$22,"<="&$Q9,'Discount Schedules'!$M$6:$M$22,">="&$Q9),"")) -> 0.04 | S9: =IF(D9="Corn",ROUND(M9/56,0),ROUND(M9/60,0)) -> 848
A10: T1009 | B10: C26007 | C10: Ridgeview Ag | D10: Corn | E10: Houston | F10: Jake Miller | G10: TX-4821 | H10: 46267 | I10: 0.38958333 | J10: 0.39930556 | K10: 81240 | L10: 32320 | M10: =K10-L10 -> 48920 | N10: 56.7 | O10: 14.6 | P10: 1.8 | Q10: 0.9 | R10: =IF($D10="Corn", SUMIFS('Discount Schedules'!$I$6:$I$22,'Discount Schedules'!$F$6:$F$22,"Moisture",'Discount Schedules'!$G$6:$G$22,"<="&$O10,'Discount Schedules'!$H$6:$H$22,">="&$O10) +SUMIFS('Discount Schedules'!$I$6:$I$22,'Discount Schedules'!$F$6:$F$22,"Test Weight",'Discount Schedules'!$G$6:$G$22,"<="&$N10,'Discount Schedules'!$H$6:$H$22,">="&$N10) +SUMIFS('Discount Schedules'!$I$6:$I$22,'Discount Schedules'!$F$6:$F$22,"Damage",'Discount Schedules'!$G$6:$G$22,"<="&$P10,'Discount Schedules'!$H$6:$H$22,">="&$P10) +SUMIFS('Discount Schedules'!$I$6:$I$22,'Discount Schedules'!$F$6:$F$22,"FM",'Discount Schedules'!$G$6:$G$22,"<="&$Q10,'Discount Schedules'!$H$6:$H$22,">="&$Q10), IF($D10="Soybeans", SUMIFS('Discount Schedules'!$N$6:$N$22,'Discount Schedules'!$K$6:$K$22,"Moisture",'Discount Schedules'!$L$6:$L$22,"<="&$O10,'Discount Schedules'!$M$6:$M$22,">="&$O10) +SUMIFS('Discount Schedules'!$N$6:$N$22,'Discount Schedules'!$K$6:$K$22,"Test Weight",'Discount Schedules'!$L$6:$L$22,"<="&$N10,'Discount Schedules'!$M$6:$M$22,">="&$N10) +SUMIFS('Discount Schedules'!$N$6:$N$22,'Discount Schedules'!$K$6:$K$22,"Damage",'Discount Schedules'!$L$6:$L$22,"<="&$P10,'Discount Schedules'!$M$6:$M$22,">="&$P10) +SUMIFS('Discount Schedules'!$N$6:$N$22,'Discount Schedules'!$K$6:$K$22,"FM",'Discount Schedules'!$L$6:$L$22,"<="&$Q10,'Discount Schedules'!$M$6:$M$22,">="&$Q10),"")) -> 0 | S10: =IF(D10="Corn",ROUND(M10/56,0),ROUND(M10/60,0)) -> 874
A11: T1010 | B11: C26005 | C11: Hoffman Farms | D11: Corn | E11: Houston | F11: Ryan Davis | G11: TX-2207 | H11: 46267 | I11: 0.40069444 | J11: 0.41041667 | K11: 77520 | L11: 30940 | M11: =K11-L11 -> 46580 | N11: 55.5 | O11: 15.7 | P11: 55.5 | Q11: 1.5 | R11: =IF($D11="Corn", SUMIFS('Discount Schedules'!$I$6:$I$22,'Discount Schedules'!$F$6:$F$22,"Moisture",'Discount Schedules'!$G$6:$G$22,"<="&$O11,'Discount Schedules'!$H$6:$H$22,">="&$O11) +SUMIFS('Discount Schedules'!$I$6:$I$22,'Discount Schedules'!$F$6:$F$22,"Test Weight",'Discount Schedules'!$G$6:$G$22,"<="&$N11,'Discount Schedules'!$H$6:$H$22,">="&$N11) +SUMIFS('Discount Schedules'!$I$6:$I$22,'Discount Schedules'!$F$6:$F$22,"Damage",'Discount Schedules'!$G$6:$G$22,"<="&$P11,'Discount Schedules'!$H$6:$H$22,">="&$P11) +SUMIFS('Discount Schedules'!$I$6:$I$22,'Discount Schedules'!$F$6:$F$22,"FM",'Discount Schedules'!$G$6:$G$22,"<="&$Q11,'Discount Schedules'!$H$6:$H$22,">="&$Q11), IF($D11="Soybeans", SUMIFS('Discount Schedules'!$N$6:$N$22,'Discount Schedules'!$K$6:$K$22,"Moisture",'Discount Schedules'!$L$6:$L$22,"<="&$O11,'Discount Schedules'!$M$6:$M$22,">="&$O11) +SUMIFS('Discount Schedules'!$N$6:$N$22,'Discount Schedules'!$K$6:$K$22,"Test Weight",'Discount Schedules'!$L$6:$L$22,"<="&$N11,'Discount Schedules'!$M$6:$M$22,">="&$N11) +SUMIFS('Discount Schedules'!$N$6:$N$22,'Discount Schedules'!$K$6:$K$22,"Damage",'Discount Schedules'!$L$6:$L$22,"<="&$P11,'Discount Schedules'!$M$6:$M$22,">="&$P11) +SUMIFS('Discount Schedules'!$N$6:$N$22,'Discount Schedules'!$K$6:$K$22,"FM",'Discount Schedules'!$L$6:$L$22,"<="&$Q11,'Discount Schedules'!$M$6:$M$22,">="&$Q11),"")) -> 0.29 | S11: =IF(D11="Corn",ROUND(M11/56,0),ROUND(M11/60,0)) -> 832
A12: T1011 | B12: S26003 | C12: Miller Farms | D12: Soybeans | E12: Houston | F12: Cody Smith | G12: TX-7932 | H12: 46267 | I12: 0.4125 | J12: 0.42361111 | K12: 79460 | L12: 30240 | M12: =K12-L12 -> 49220 | N12: 58.3 | O12: 13.4 | P12: 1.2 | Q12: 0.7 | R12: =IF($D12="Corn", SUMIFS('Discount Schedules'!$I$6:$I$22,'Discount Schedules'!$F$6:$F$22,"Moisture",'Discount Schedules'!$G$6:$G$22,"<="&$O12,'Discount Schedules'!$H$6:$H$22,">="&$O12) +SUMIFS('Discount Schedules'!$I$6:$I$22,'Discount Schedules'!$F$6:$F$22,"Test Weight",'Discount Schedules'!$G$6:$G$22,"<="&$N12,'Discount Schedules'!$H$6:$H$22,">="&$N12) +SUMIFS('Discount Schedules'!$I$6:$I$22,'Discount Schedules'!$F$6:$F$22,"Damage",'Discount Schedules'!$G$6:$G$22,"<="&$P12,'Discount Schedules'!$H$6:$H$22,">="&$P12) +SUMIFS('Discount Schedules'!$I$6:$I$22,'Discount Schedules'!$F$6:$F$22,"FM",'Discount Schedules'!$G$6:$G$22,"<="&$Q12,'Discount Schedules'!$H$6:$H$22,">="&$Q12), IF($D12="Soybeans", SUMIFS('Discount Schedules'!$N$6:$N$22,'Discount Schedules'!$K$6:$K$22,"Moisture",'Discount Schedules'!$L$6:$L$22,"<="&$O12,'Discount Schedules'!$M$6:$M$22,">="&$O12) +SUMIFS('Discount Schedules'!$N$6:$N$22,'Discount Schedules'!$K$6:$K$22,"Test Weight",'Discount Schedules'!$L$6:$L$22,"<="&$N12,'Discount Schedules'!$M$6:$M$22,">="&$N12) +SUMIFS('Discount Schedules'!$N$6:$N$22,'Discount Schedules'!$K$6:$K$22,"Damage",'Discount Schedules'!$L$6:$L$22,"<="&$P12,'Discount Schedules'!$M$6:$M$22,">="&$P12) +SUMIFS('Discount Schedules'!$N$6:$N$22,'Discount Schedules'!$K$6:$K$22,"FM",'Discount Schedules'!$L$6:$L$22,"<="&$Q12,'Discount Schedules'!$M$6:$M$22,">="&$Q12),"")) -> 0.01 | S12: =IF(D12="Corn",ROUND(M12/56,0),ROUND(M12/60,0)) -> 820
A13: T1012 | B13: C26008 | C13: Triple Creek Farm | D13: Corn | E13: Houston | F13: Matt Wilson | G13: TX-5189 | H13: 46267 | I13: 0.42222222 | J13: 0.43194444 | K13: 80780 | L13: 31880 | M13: =K13-L13 -> 48900 | N13: 56.8 | O13: 14.9 | P13: 1.7 | Q13: 0.8 | R13: =IF($D13="Corn", SUMIFS('Discount Schedules'!$I$6:$I$22,'Discount Schedules'!$F$6:$F$22,"Moisture",'Discount Schedules'!$G$6:$G$22,"<="&$O13,'Discount Schedules'!$H$6:$H$22,">="&$O13) +SUMIFS('Discount Schedules'!$I$6:$I$22,'Discount Schedules'!$F$6:$F$22,"Test Weight",'Discount Schedules'!$G$6:$G$22,"<="&$N13,'Discount Schedules'!$H$6:$H$22,">="&$N13) +SUMIFS('Discount Schedules'!$I$6:$I$22,'Discount Schedules'!$F$6:$F$22,"Damage",'Discount Schedules'!$G$6:$G$22,"<="&$P13,'Discount Schedules'!$H$6:$H$22,">="&$P13) +SUMIFS('Discount Schedules'!$I$6:$I$22,'Discount Schedules'!$F$6:$F$22,"FM",'Discount Schedules'!$G$6:$G$22,"<="&$Q13,'Discount Schedules'!$H$6:$H$22,">="&$Q13), IF($D13="Soybeans", SUMIFS('Discount Schedules'!$N$6:$N$22,'Discount Schedules'!$K$6:$K$22,"Moisture",'Discount Schedules'!$L$6:$L$22,"<="&$O13,'Discount Schedules'!$M$6:$M$22,">="&$O13) +SUMIFS('Discount Schedules'!$N$6:$N$22,'Discount Schedules'!$K$6:$K$22,"Test Weight",'Discount Schedules'!$L$6:$L$22,"<="&$N13,'Discount Schedules'!$M$6:$M$22,">="&$N13) +SUMIFS('Discount Schedules'!$N$6:$N$22,'Discount Schedules'!$K$6:$K$22,"Damage",'Discount Schedules'!$L$6:$L$22,"<="&$P13,'Discount Schedules'!$M$6:$M$22,">="&$P13) +SUMIFS('Discount Schedules'!$N$6:$N$22,'Discount Schedules'!$K$6:$K$22,"FM",'Discount Schedules'!$L$6:$L$22,"<="&$Q13,'Discount Schedules'!$M$6:$M$22,">="&$Q13),"")) -> 0 | S13: =IF(D13="Corn",ROUND(M13/56,0),ROUND(M13/60,0)) -> 873
... A31: T1030 | B31: C26007 | C31: Ridgeview Ag | D31: Corn | E31: Houston | F31: Jake Miller | G31: TX-4821 | H31: 46267 | I31: 0.64513889 | J31: 0.65416667 | K31: 81280 | L31: 32180 | M31: =K31-L31 -> 49100 | N31: 56.8 | O31: 14.5 | P31: 1.8 | Q31: 0.9 | R31: =IF($D31="Corn", SUMIFS('Discount Schedules'!$I$6:$I$22,'Discount Schedules'!$F$6:$F$22,"Moisture",'Discount Schedules'!$G$6:$G$22,"<="&$O31,'Discount Schedules'!$H$6:$H$22,">="&$O31) +SUMIFS('Discount Schedules'!$I$6:$I$22,'Discount Schedules'!$F$6:$F$22,"Test Weight",'Discount Schedules'!$G$6:$G$22,"<="&$N31,'Discount Schedules'!$H$6:$H$22,">="&$N31) +SUMIFS('Discount Schedules'!$I$6:$I$22,'Discount Schedules'!$F$6:$F$22,"Damage",'Discount Schedules'!$G$6:$G$22,"<="&$P31,'Discount Schedules'!$H$6:$H$22,">="&$P31) +SUMIFS('Discount Schedules'!$I$6:$I$22,'Discount Schedules'!$F$6:$F$22,"FM",'Discount Schedules'!$G$6:$G$22,"<="&$Q31,'Discount Schedules'!$H$6:$H$22,">="&$Q31), IF($D31="Soybeans", SUMIFS('Discount Schedules'!$N$6:$N$22,'Discount Schedules'!$K$6:$K$22,"Moisture",'Discount Schedules'!$L$6:$L$22,"<="&$O31,'Discount Schedules'!$M$6:$M$22,">="&$O31) +SUMIFS('Discount Schedules'!$N$6:$N$22,'Discount Schedules'!$K$6:$K$22,"Test Weight",'Discount Schedules'!$L$6:$L$22,"<="&$N31,'Discount Schedules'!$M$6:$M$22,">="&$N31) +SUMIFS('Discount Schedules'!$N$6:$N$22,'Discount Schedules'!$K$6:$K$22,"Damage",'Discount Schedules'!$L$6:$L$22,"<="&$P31,'Discount Schedules'!$M$6:$M$22,">="&$P31) +SUMIFS('Discount Schedules'!$N$6:$N$22,'Discount Schedules'!$K$6:$K$22,"FM",'Discount Schedules'!$L$6:$L$22,"<="&$Q31,'Discount Schedules'!$M$6:$M$22,">="&$Q31),"")) -> 0 | S31: =IF(D31="Corn",ROUND(M31/56,0),ROUND(M31/60,0)) -> 877

Sheet Discount Schedules
F1: Dockage values are cumulative and applied per bushel based on ticket quality results.*
F4: Corn Discount Schedule | K4: Soybean Discount Schedule
F5: Factor | G5: Low | H5: High | I5: Dockage ($/bu) | K5: Factor | L5: Low | M5: High | N5: Dockage ($/bu)
F6: Moisture | G6: 15.1 | H6: 16 | I6: 0.02 | K6: Moisture | L6: 13.1 | M6: 14 | N6: 0.01
F7: Moisture | G7: 16.1 | H7: 17 | I7: 0.04 | K7: Moisture | L7: 14.1 | M7: 15 | N7: 0.03
F8: Moisture | G8: 17.1 | H8: 18 | I8: 0.08 | K8: Moisture | L8: 15.1 | M8: 16 | N8: 0.06
F9: Moisture | G9: 18.1 | H9: 19 | I9: 0.12 | K9: Moisture | L9: 16.1 | M9: 17 | N9: 0.1
F10: Moisture | G10: 19.1 | H10: 20 | I10: 0.18 | K10: Moisture | L10: 17.1 | M10: 18 | N10: 0.15
F11: Moisture | G11: 20.1 | H11: 99.9 | I11: 0.25 | K11: Moisture | L11: 18.1 | M11: 99.9 | N11: 0.25
F12: Test Weight | G12: 54 | H12: 54.9 | I12: 0.02 | K12: Test Weight | L12: 55 | M12: 55.9 | N12: 0.02
F13: Test Weight | G13: 53 | H13: 53.9 | I13: 0.05 | K13: Test Weight | L13: 54 | M13: 54.9 | N13: 0.05
F14: Test Weight | G14: 52 | H14: 52.9 | I14: 0.1 | K14: Test Weight | L14: 53 | M14: 53.9 | N14: 0.1
F15: Test Weight | G15: 51 | H15: 51.9 | I15: 0.15 | K15: Test Weight | L15: 52 | M15: 52.9 | N15: 0.15
F16: Damage | G16: 3.1 | H16: 4 | I16: 0.03 | K16: Damage | L16: 3.1 | M16: 4 | N16: 0.03
F17: Damage | G17: 4.1 | H17: 5 | I17: 0.08 | K17: Damage | L17: 4.1 | M17: 5 | N17: 0.08
... F22: FM | G22: 3.1 | H22: 99.9 | I22: 0.1 | K22: FM | L22: 3.1 | M22: 99.9 | N22: 0.1

Sheet Sale Contracts
A1: Sale Cxt # | B1: Buyer | C1: Commodity | D1: Destination | E1: DLV Period | F1: Futures Code | G1: Fut Px | H1: Dest Basis | I1: Freight Adj | J1: Net Basis | K1: Sale Px | L1: Bushels | M1: Shipped | N1: Remaining | O1: Fill %
A2: SC26001 | B2: Bayport Ethanol | C2: Corn | D2: Pasadena, TX | E2: 46079 | F2: CH26 | G2: 4.87 | H2: -0.12 | I2: =_xlfn.XLOOKUP($D2,$D$19:$D$25,$F$19:$F$25) -> -0.02 | J2: =H2+I2 -> -0.14 | K2: =G2+J2 -> 4.73 | L2: 8000 | M2: =SUMIF('Outbound Scale Tickets'!$B:$B,$A2,'Outbound Scale Tickets'!$S:$S) -> 1713.2143 | N2: =$L2-$M2 -> 6286.7857 | O2: =($M2/$L2) -> 0.21415179
A3: SC26002 | B3: Gulf Coast Feed | C3: Corn | D3: Humble, TX | E3: 46107 | F3: CH26 | G3: 4.92 | H3: -0.15 | I3: =_xlfn.XLOOKUP($D3,$D$19:$D$25,$F$19:$F$25) -> -0.08 | J3: =H3+I3 -> -0.23 | K3: =G3+J3 -> 4.69 | L3: 12000 | M3: =SUMIF('Outbound Scale Tickets'!$B:$B,$A3,'Outbound Scale Tickets'!$S:$S) -> 867.5 | N3: =$L3-$M3 -> 11132.5 | O3: =($M3/$L3) -> 0.072291667
A4: SC26003 | B4: Porter Feed Mill | C4: Corn | D4: Porter, TX | E4: 46199 | F4: CN26 | G4: 5.08 | H4: -0.08 | I4: =_xlfn.XLOOKUP($D4,$D$19:$D$25,$F$19:$F$25) -> -0.12 | J4: =H4+I4 -> -0.2 | K4: =G4+J4 -> 4.88 | L4: 10000 | M4: =SUMIF('Outbound Scale Tickets'!$B:$B,$A4,'Outbound Scale Tickets'!$S:$S) -> 875.71429 | N4: =$L4-$M4 -> 9124.2857 | O4: =($M4/$L4) -> 0.087571429
A5: SC26004 | B5: Lone Star Export | C5: Corn | D5: Galveston, TX | E5: 46291 | F5: CU26 | G5: 5.01 | H5: 0.05 | I5: =_xlfn.XLOOKUP($D5,$D$19:$D$25,$F$19:$F$25) -> -0.15 | J5: =H5+I5 -> -0.1 | K5: =G5+J5 -> 4.91 | L5: 15000 | M5: =SUMIF('Outbound Scale Tickets'!$B:$B,$A5,'Outbound Scale Tickets'!$S:$S) -> 883.57143 | N5: =$L5-$M5 -> 14116.429 | O5: =($M5/$L5) -> 0.058904762
A6: SC26005 | B6: Sugar Land Milling | C6: Corn | D6: Sugar Land, TX | E6: Oct-Nov 26 | F6: CZ26 | G6: 4.78 | H6: -0.05 | I6: =_xlfn.XLOOKUP($D6,$D$19:$D$25,$F$19:$F$25) -> -0.1 | J6: =H6+I6 -> -0.15 | K6: =G6+J6 -> 4.63 | L6: 10000 | M6: =SUMIF('Outbound Scale Tickets'!$B:$B,$A6,'Outbound Scale Tickets'!$S:$S) -> 869.64286 | N6: =$L6-$M6 -> 9130.3571 | O6: =($M6/$L6) -> 0.086964286
A7: SC26006 | B7: Enterprise Ethanol | C7: Corn | D7: Mont Belvieu, TX | E7: 46260 | F7: CU26 | G7: 5.12 | H7: -0.1 | I7: =_xlfn.XLOOKUP($D7,$D$19:$D$25,$F$19:$F$25) -> -0.06 | J7: =H7+I7 -> -0.16 | K7: =G7+J7 -> 4.96 | L7: 9000 | M7: =SUMIF('Outbound Scale Tickets'!$B:$B,$A7,'Outbound Scale Tickets'!$S:$S) -> 878.57143 | N7: =$L7-$M7 -> 8121.4286 | O7: =($M7/$L7) -> 0.097619048
A8: SC26007 | B8: Texas Feed Group | C8: Corn | D8: Pasadena, TX | E8: 46352 | F8: CZ26 | G8: 4.85 | H8: -0.18 | I8: =_xlfn.XLOOKUP($D8,$D$19:$D$25,$F$19:$F$25) -> -0.02 | J8: =H8+I8 -> -0.2 | K8: =G8+J8 -> 4.65 | L8: 11000 | M8: =SUMIF('Outbound Scale Tickets'!$B:$B,$A8,'Outbound Scale Tickets'!$S:$S) -> 887.5 | N8: =$L8-$M8 -> 10112.5 | O8: =($M8/$L8) -> 0.080681818
A9: SS26001 | B9: Texas Soy Processors | C9: Soybeans | D9: Mont Belvieu, TX | E9: 46260 | F9: SQ26 | G9: 10.58 | H9: -0.2 | I9: =_xlfn.XLOOKUP($D9,$D$19:$D$25,$F$19:$F$25) -> -0.06 | J9: =H9+I9 -> -0.26 | K9: =G9+J9 -> 10.32 | L9: 6000 | M9: =SUMIF('Outbound Scale Tickets'!$B:$B,$A9,'Outbound Scale Tickets'!$S:$S) -> 816.66667 | N9: =$L9-$M9 -> 5183.3333 | O9: =($M9/$L9) -> 0.13611111
A10: SS26002 | B10: Gulf Export Terminal | C10: Soybeans | D10: Galveston, TX | E10: Oct-Nov 26 | F10: SX26 | G10: 10.95 | H10: 0.1 | I10: =_xlfn.XLOOKUP($D10,$D$19:$D$25,$F$19:$F$25) -> -0.15 | J10: =H10+I10 -> -0.05 | K10: =G10+J10 -> 10.9 | L10: 10000 | M10: =SUMIF('Outbound Scale Tickets'!$B:$B,$A10,'Outbound Scale Tickets'!$S:$S) -> 830 | N10: =$L10-$M10 -> 9170 | O10: =($M10/$L10) -> 0.083
A11: SS26003 | B11: Heritage Feed & Oil | C11: Soybeans | D11: Porter, TX | E11: 46352 | F11: SX26 | G11: 11.05 | H11: -0.15 | I11: =_xlfn.XLOOKUP($D11,$D$19:$D$25,$F$19:$F$25) -> -0.12 | J11: =H11+I11 -> -0.27 | K11: =G11+J11 -> 10.78 | L11: 7000 | M11: =SUMIF('Outbound Scale Tickets'!$B:$B,$A11,'Outbound Scale Tickets'!$S:$S) -> 823.33333 | N11: =$L11-$M11 -> 6176.6667 | O11: =($M11/$L11) -> 0.11761905
A12: SS26004 | B12: Bay Area Crushing | C12: Soybeans | D12: Pasadena, TX | E12: 46291 | F12: SU26 | G12: 10.72 | H12: -0.1 | I12: =_xlfn.XLOOKUP($D12,$D$19:$D$25,$F$19:$F$25) -> -0.02 | J12: =H12+I12 -> -0.12 | K12: =G12+J12 -> 10.6 | L12: 8000 | M12: =SUMIF('Outbound Scale Tickets'!$B:$B,$A12,'Outbound Scale Tickets'!$S:$S) -> 0 | N12: =$L12-$M12 -> 8000 | O12: =($M12/$L12) -> 0
A13: SS26005 | B13: Lone Star Soy Processing | C13: Soybeans | D13: Humble, TX | E13: 46321 | F13: SX26 | G13: 10.88 | H13: -0.12 | I13: =_xlfn.XLOOKUP($D13,$D$19:$D$25,$F$19:$F$25) -> -0.08 | J13: =H13+I13 -> -0.2 | K13: =G13+J13 -> 10.68 | L13: 9000 | M13: =SUMIF('Outbound Scale Tickets'!$B:$B,$A13,'Outbound Scale Tickets'!$S:$S) -> 0 | N13: =$L13-$M13 -> 9000 | O13: =($M13/$L13) -> 0
A14: SS26006 | B14: Coastal Export Group | C14: Soybeans | D14: Galveston, TX | E14: 46352 | F14: SX26 | G14: 11.12 | H14: 0.08 | I14: =_xlfn.XLOOKUP($D14,$D$19:$D$25,$F$19:$F$25) -> -0.15 | J14: =H14+I14 -> -0.07 | K14: =G14+J14 -> 11.05 | L14: 12000 | M14: =SUMIF('Outbound Scale Tickets'!$B:$B,$A14,'Outbound Scale Tickets'!$S:$S) -> 0 | N14: =$L14-$M14 -> 12000 | O14: =($M14/$L14) -> 0
D17: Destination Freight Rates
D18: Location | F18: Freight Adj ($/bu)
D19: Houston, TX | F19: 0
D20: Pasadena, TX | F20: -0.02
D21: Humble, TX | F21: -0.08
D22: Porter, TX | F22: -0.12
D23: Sugar Land, TX | F23: -0.1
D24: Mont Belvieu, TX | F24: -0.06
D25: Galveston, TX | F25: -0.15

Sheet Outbound Scale Tickets
A1: Ticket # | B1: Sale Contract # | C1: Buyer | D1: Commodity | E1: Destination | F1: Driver | G1: License Plate | H1: Ship Date | I1: Time Out | J1: Time In | K1: Gross Wt | L1: Tare Wt | M1: Net Wt | N1: TW | O1: Mt % | P1: Dmg % | Q1: FM % | R1: Dest Dockage ($/bu) | S1: Net Bu | T1: Dest Deduction ($)
A2: OT1001 | B2: SC26001 | C2: Bayport Ethanol | D2: Corn | E2: Pasadena, TX | F2: Jake Miller | G2: TX-4821 | H2: 46268 | I2: 0.3 | J2: 0.30902778 | K2: 80240 | L2: 32180 | M2: =K2-L2 -> 48060 | N2: 56.6 | O2: 15.2 | P2: 3.5 | Q2: 1.5 | R2: =SUMIFS('Destination Specs'!$GL$315:$GL$450,'Destination Specs'!$GG$315:$GG$450,$C2,'Destination Specs'!$GI$315:$GI$450,"MT",'Destination Specs'!$GJ$315:$GJ$450,"<="&$O2,'Destination Specs'!$GK$315:$GK$450,">="&$O2)+SUMIFS('Destination Specs'!$GL$315:$GL$450,'Destination Specs'!$GG$315:$GG$450,$C2,'Destination Specs'!$GI$315:$GI$450,"DMG",'Destination Specs'!$GJ$315:$GJ$450,"<="&$P2,'Destination Specs'!$GK$315:$GK$450,">="&$P2)+SUMIFS('Destination Specs'!$GL$315:$GL$450,'Destination Specs'!$GG$315:$GG$450,$C2,'Destination Specs'!$GI$315:$GI$450,"FM",'Destination Specs'!$GJ$315:$GJ$450,"<="&$Q2,'Destination Specs'!$GK$315:$GK$450,">="&$Q2) -> 0.07 | S2: =IF(D2="Corn",M2/56,M2/60) -> 858.21429 | T2: =R2*S2 -> 60.075
A3: OT1002 | B3: SC26001 | C3: Bayport Ethanol | D3: Corn | E3: Pasadena, TX | F3: Matt Wilson | G3: TX-5189 | H3: 46268 | I3: 0.33402778 | J3: 0.34305556 | K3: 79860 | L3: 31980 | M3: =K3-L3 -> 47880 | N3: 56.4 | O3: 14.8 | P3: 2.8 | Q3: 1 | R3: =SUMIFS('Destination Specs'!$GL$315:$GL$450,'Destination Specs'!$GG$315:$GG$450,$C3,'Destination Specs'!$GI$315:$GI$450,"MT",'Destination Specs'!$GJ$315:$GJ$450,"<="&$O3,'Destination Specs'!$GK$315:$GK$450,">="&$O3)+SUMIFS('Destination Specs'!$GL$315:$GL$450,'Destination Specs'!$GG$315:$GG$450,$C3,'Destination Specs'!$GI$315:$GI$450,"DMG",'Destination Specs'!$GJ$315:$GJ$450,"<="&$P3,'Destination Specs'!$GK$315:$GK$450,">="&$P3)+SUMIFS('Destination Specs'!$GL$315:$GL$450,'Destination Specs'!$GG$315:$GG$450,$C3,'Destination Specs'!$GI$315:$GI$450,"FM",'Destination Specs'!$GJ$315:$GJ$450,"<="&$Q3,'Destination Specs'!$GK$315:$GK$450,">="&$Q3) -> 0 | S3: =IF(D3="Corn",M3/56,M3/60) -> 855 | T3: =R3*S3 -> 0
A4: OT1003 | B4: SC26002 | C4: Gulf Coast Feed | D4: Corn | E4: Humble, TX | F4: Ryan Davis | G4: TX-2207 | H4: 46268 | I4: 0.37152778 | J4: 0.38125 | K4: 80620 | L4: 32040 | M4: =K4-L4 -> 48580 | N4: 54.8 | O4: 15.6 | P4: 4.2 | Q4: 2.2 | R4: =SUMIFS('Destination Specs'!$GL$315:$GL$450,'Destination Specs'!$GG$315:$GG$450,$C4,'Destination Specs'!$GI$315:$GI$450,"MT",'Destination Specs'!$GJ$315:$GJ$450,"<="&$O4,'Destination Specs'!$GK$315:$GK$450,">="&$O4)+SUMIFS('Destination Specs'!$GL$315:$GL$450,'Destination Specs'!$GG$315:$GG$450,$C4,'Destination Specs'!$GI$315:$GI$450,"DMG",'Destination Specs'!$GJ$315:$GJ$450,"<="&$P4,'Destination Specs'!$GK$315:$GK$450,">="&$P4)+SUMIFS('Destination Specs'!$GL$315:$GL$450,'Destination Specs'!$GG$315:$GG$450,$C4,'Destination Specs'!$GI$315:$GI$450,"FM",'Destination Specs'!$GJ$315:$GJ$450,"<="&$Q4,'Destination Specs'!$GK$315:$GK$450,">="&$Q4) -> 0.15 | S4: =IF(D4="Corn",M4/56,M4/60) -> 867.5 | T4: =R4*S4 -> 130.125
A5: OT1004 | B5: SC26003 | C5: Porter Feed Mill | D5: Corn | E5: Porter, TX | F5: Cody Smith | G5: TX-7932 | H5: 46268 | I5: 0.40069444 | J5: 0.41111111 | K5: 81240 | L5: 32200 | M5: =K5-L5 -> 49040 | N5: 55.2 | O5: 16.2 | P5: 3.8 | Q5: 2.5 | R5: =SUMIFS('Destination Specs'!$GL$315:$GL$450,'Destination Specs'!$GG$315:$GG$450,$C5,'Destination Specs'!$GI$315:$GI$450,"MT",'Destination Specs'!$GJ$315:$GJ$450,"<="&$O5,'Destination Specs'!$GK$315:$GK$450,">="&$O5)+SUMIFS('Destination Specs'!$GL$315:$GL$450,'Destination Specs'!$GG$315:$GG$450,$C5,'Destination Specs'!$GI$315:$GI$450,"DMG",'Destination Specs'!$GJ$315:$GJ$450,"<="&$P5,'Destination Specs'!$GK$315:$GK$450,">="&$P5)+SUMIFS('Destination Specs'!$GL$315:$GL$450,'Destination Specs'!$GG$315:$GG$450,$C5,'Destination Specs'!$GI$315:$GI$450,"FM",'Destination Specs'!$GJ$315:$GJ$450,"<="&$Q5,'Destination Specs'!$GK$315:$GK$450,">="&$Q5) -> 0.13 | S5: =IF(D5="Corn",M5/56,M5/60) -> 875.71429 | T5: =R5*S5 -> 113.84286
A6: OT1005 | B6: SC26004 | C6: Lone Star Export | D6: Corn | E6: Galveston, TX | F6: Jake Miller | G6: TX-4821 | H6: 46268 | I6: 0.42708333 | J6: 0.43819444 | K6: 81820 | L6: 32340 | M6: =K6-L6 -> 49480 | N6: 56.8 | O6: 14.9 | P6: 2.5 | Q6: 0.9 | R6: =SUMIFS('Destination Specs'!$GL$315:$GL$450,'Destination Specs'!$GG$315:$GG$450,$C6,'Destination Specs'!$GI$315:$GI$450,"MT",'Destination Specs'!$GJ$315:$GJ$450,"<="&$O6,'Destination Specs'!$GK$315:$GK$450,">="&$O6)+SUMIFS('Destination Specs'!$GL$315:$GL$450,'Destination Specs'!$GG$315:$GG$450,$C6,'Destination Specs'!$GI$315:$GI$450,"DMG",'Destination Specs'!$GJ$315:$GJ$450,"<="&$P6,'Destination Specs'!$GK$315:$GK$450,">="&$P6)+SUMIFS('Destination Specs'!$GL$315:$GL$450,'Destination Specs'!$GG$315:$GG$450,$C6,'Destination Specs'!$GI$315:$GI$450,"FM",'Destination Specs'!$GJ$315:$GJ$450,"<="&$Q6,'Destination Specs'!$GK$315:$GK$450,">="&$Q6) -> 0.11 | S6: =IF(D6="Corn",M6/56,M6/60) -> 883.57143 | T6: =R6*S6 -> 97.192857
A7: OT1006 | B7: SC26005 | C7: Sugar Land Milling | D7: Corn | E7: Sugar Land, TX | F7: Travis Johnson | G7: TX-6154 | H7: 46268 | I7: 0.46041667 | J7: 0.47083333 | K7: 80820 | L7: 32120 | M7: =K7-L7 -> 48700 | N7: 54.5 | O7: 15.7 | P7: 4.8 | Q7: 2.8 | R7: =SUMIFS('Destination Specs'!$GL$315:$GL$450,'Destination Specs'!$GG$315:$GG$450,$C7,'Destination Specs'!$GI$315:$GI$450,"MT",'Destination Specs'!$GJ$315:$GJ$450,"<="&$O7,'Destination Specs'!$GK$315:$GK$450,">="&$O7)+SUMIFS('Destination Specs'!$GL$315:$GL$450,'Destination Specs'!$GG$315:$GG$450,$C7,'Destination Specs'!$GI$315:$GI$450,"DMG",'Destination Specs'!$GJ$315:$GJ$450,"<="&$P7,'Destination Specs'!$GK$315:$GK$450,">="&$P7)+SUMIFS('Destination Specs'!$GL$315:$GL$450,'Destination Specs'!$GG$315:$GG$450,$C7,'Destination Specs'!$GI$315:$GI$450,"FM",'Destination Specs'!$GJ$315:$GJ$450,"<="&$Q7,'Destination Specs'!$GK$315:$GK$450,">="&$Q7) -> 0.15 | S7: =IF(D7="Corn",M7/56,M7/60) -> 869.64286 | T7: =R7*S7 -> 130.44643
A8: OT1007 | B8: SC26006 | C8: Enterprise Ethanol | D8: Corn | E8: Mont Belvieu, TX | F8: Matt Wilson | G8: TX-5189 | H8: 46268 | I8: 0.49444444 | J8: 0.50555556 | K8: 81460 | L8: 32260 | M8: =K8-L8 -> 49200 | N8: 56.1 | O8: 15.3 | P8: 3.2 | Q8: 1.6 | R8: =SUMIFS('Destination Specs'!$GL$315:$GL$450,'Destination Specs'!$GG$315:$GG$450,$C8,'Destination Specs'!$GI$315:$GI$450,"MT",'Destination Specs'!$GJ$315:$GJ$450,"<="&$O8,'Destination Specs'!$GK$315:$GK$450,">="&$O8)+SUMIFS('Destination Specs'!$GL$315:$GL$450,'Destination Specs'!$GG$315:$GG$450,$C8,'Destination Specs'!$GI$315:$GI$450,"DMG",'Destination Specs'!$GJ$315:$GJ$450,"<="&$P8,'Destination Specs'!$GK$315:$GK$450,">="&$P8)+SUMIFS('Destination Specs'!$GL$315:$GL$450,'Destination Specs'!$GG$315:$GG$450,$C8,'Destination Specs'!$GI$315:$GI$450,"FM",'Destination Specs'!$GJ$315:$GJ$450,"<="&$Q8,'Destination Specs'!$GK$315:$GK$450,">="&$Q8) -> 0.07 | S8: =IF(D8="Corn",M8/56,M8/60) -> 878.57143 | T8: =R8*S8 -> 61.5
A9: OT1008 | B9: SC26007 | C9: Texas Feed Group | D9: Corn | E9: Pasadena, TX | F9: Ryan Davis | G9: TX-2207 | H9: 46268 | I9: 0.54444444 | J9: 0.55416667 | K9: 82100 | L9: 32400 | M9: =K9-L9 -> 49700 | N9: 55 | O9: 16.4 | P9: 4.5 | Q9: 2.4 | R9: =SUMIFS('Destination Specs'!$GL$315:$GL$450,'Destination Specs'!$GG$315:$GG$450,$C9,'Destination Specs'!$GI$315:$GI$450,"MT",'Destination Specs'!$GJ$315:$GJ$450,"<="&$O9,'Destination Specs'!$GK$315:$GK$450,">="&$O9)+SUMIFS('Destination Specs'!$GL$315:$GL$450,'Destination Specs'!$GG$315:$GG$450,$C9,'Destination Specs'!$GI$315:$GI$450,"DMG",'Destination Specs'!$GJ$315:$GJ$450,"<="&$P9,'Destination Specs'!$GK$315:$GK$450,">="&$P9)+SUMIFS('Destination Specs'!$GL$315:$GL$450,'Destination Specs'!$GG$315:$GG$450,$C9,'Destination Specs'!$GI$315:$GI$450,"FM",'Destination Specs'!$GJ$315:$GJ$450,"<="&$Q9,'Destination Specs'!$GK$315:$GK$450,">="&$Q9) -> 0 | S9: =IF(D9="Corn",M9/56,M9/60) -> 887.5 | T9: =R9*S9 -> 0
A10: OT1009 | B10: SS26001 | C10: Texas Soy Processors | D10: Soybeans | E10: Mont Belvieu, TX | F10: Cody Smith | G10: TX-7932 | H10: 46268 | I10: 0.58055556 | J10: 0.58958333 | K10: 79220 | L10: 30220 | M10: =K10-L10 -> 49000 | N10: 54.2 | O10: 13.8 | P10: 3.4 | Q10: 1.5 | R10: =SUMIFS('Destination Specs'!$GL$315:$GL$450,'Destination Specs'!$GG$315:$GG$450,$C10,'Destination Specs'!$GI$315:$GI$450,"MT",'Destination Specs'!$GJ$315:$GJ$450,"<="&$O10,'Destination Specs'!$GK$315:$GK$450,">="&$O10)+SUMIFS('Destination Specs'!$GL$315:$GL$450,'Destination Specs'!$GG$315:$GG$450,$C10,'Destination Specs'!$GI$315:$GI$450,"DMG",'Destination Specs'!$GJ$315:$GJ$450,"<="&$P10,'Destination Specs'!$GK$315:$GK$450,">="&$P10)+SUMIFS('Destination Specs'!$GL$315:$GL$450,'Destination Specs'!$GG$315:$GG$450,$C10,'Destination Specs'!$GI$315:$GI$450,"FM",'Destination Specs'!$GJ$315:$GJ$450,"<="&$Q10,'Destination Specs'!$GK$315:$GK$450,">="&$Q10) -> 0.07 | S10: =IF(D10="Corn",M10/56,M10/60) -> 816.66667 | T10: =R10*S10 -> 57.166667
A11: OT1010 | B11: SS26002 | C11: Gulf Export Terminal | D11: Soybeans | E11: Galveston, TX | F11: Jake Miller | G11: TX-4821 | H11: 46268 | I11: 0.61388889 | J11: 0.62361111 | K11: 80480 | L11: 30680 | M11: =K11-L11 -> 49800 | N11: 54.6 | O11: 13.2 | P11: 3.7 | Q11: 0.8 | R11: =SUMIFS('Destination Specs'!$GL$315:$GL$450,'Destination Specs'!$GG$315:$GG$450,$C11,'Destination Specs'!$GI$315:$GI$450,"MT",'Destination Specs'!$GJ$315:$GJ$450,"<="&$O11,'Destination Specs'!$GK$315:$GK$450,">="&$O11)+SUMIFS('Destination Specs'!$GL$315:$GL$450,'Destination Specs'!$GG$315:$GG$450,$C11,'Destination Specs'!$GI$315:$GI$450,"DMG",'Destination Specs'!$GJ$315:$GJ$450,"<="&$P11,'Destination Specs'!$GK$315:$GK$450,">="&$P11)+SUMIFS('Destination Specs'!$GL$315:$GL$450,'Destination Specs'!$GG$315:$GG$450,$C11,'Destination Specs'!$GI$315:$GI$450,"FM",'Destination Specs'!$GJ$315:$GJ$450,"<="&$Q11,'Destination Specs'!$GK$315:$GK$450,">="&$Q11) -> 0.23 | S11: =IF(D11="Corn",M11/56,M11/60) -> 830 | T11: =R11*S11 -> 190.9
A12: OT1011 | B12: SS26003 | C12: Heritage Feed & Oil | D12: Soybeans | E12: Porter, TX | F12: Matt Wilson | G12: TX-5189 | H12: 46268 | I12: 0.6375 | J12: 0.64791667 | K12: 79840 | L12: 30440 | M12: =K12-L12 -> 49400 | N12: 53.8 | O12: 14.4 | P12: 4.2 | Q12: 2.3 | R12: =SUMIFS('Destination Specs'!$GL$315:$GL$450,'Destination Specs'!$GG$315:$GG$450,$C12,'Destination Specs'!$GI$315:$GI$450,"MT",'Destination Specs'!$GJ$315:$GJ$450,"<="&$O12,'Destination Specs'!$GK$315:$GK$450,">="&$O12)+SUMIFS('Destination Specs'!$GL$315:$GL$450,'Destination Specs'!$GG$315:$GG$450,$C12,'Destination Specs'!$GI$315:$GI$450,"DMG",'Destination Specs'!$GJ$315:$GJ$450,"<="&$P12,'Destination Specs'!$GK$315:$GK$450,">="&$P12)+SUMIFS('Destination Specs'!$GL$315:$GL$450,'Destination Specs'!$GG$315:$GG$450,$C12,'Destination Specs'!$GI$315:$GI$450,"FM",'Destination Specs'!$GJ$315:$GJ$450,"<="&$Q12,'Destination Specs'!$GK$315:$GK$450,">="&$Q12) -> 0.18 | S12: =IF(D12="Corn",M12/56,M12/60) -> 823.33333 | T12: =R12*S12 -> 148.2

Sheet Destination Specs
A1: Destination quality specifications are maintained by buyer and are used to calculate outbound dockage on shipped grain. Dockage values are cumulative and applied per bushel based on destination-specific quality standards. Export terminals generally maintain stricter quality requirements than ethanol plants, feed mills, and soybean processors.*
K5: Corn Destination Specifications
A7: Bayport Ethanol | F7: Gulf Coast Feed | K7: Porter Feed Mill | P7: Sugar Land Milling | U7: Enterprise Ethanol | Z7: Lone Star Export
A8: Factor | B8: Low | C8: High | D8: Dockage | F8: Factor | G8: Low | H8: High | I8: Dockage | K8: Factor | L8: Low | M8: High | N8: Dockage | P8: Factor | Q8: Low | R8: High | S8: Dockage | U8: Factor | V8: Low | W8: High | X8: Dockage | Z8: Factor | AA8: Low | AB8: High | AC8: Dockage
A9: MT | B9: 15.1 | C9: 16 | D9: 0.02 | F9: MT | G9: 15.1 | H9: 16 | I9: 0.02 | K9: MT | L9: 15.1 | M9: 16 | N9: 0.02 | P9: MT | Q9: 15.1 | R9: 16 | S9: 0.02 | U9: MT | V9: 15.1 | W9: 16 | X9: 0.02 | Z9: MT | AA9: 14.6 | AB9: 15 | AC9: 0.03
A10: MT | B10: 16.1 | C10: 17 | D10: 0.05 | F10: MT | G10: 16.1 | H10: 17 | I10: 0.05 | K10: MT | L10: 16.1 | M10: 17 | N10: 0.05 | P10: MT | Q10: 16.1 | R10: 17 | S10: 0.05 | U10: MT | V10: 16.1 | W10: 17 | X10: 0.05 | Z10: MT | AA10: 15.1 | AB10: 16 | AC10: 0.08
A11: MT | B11: 17.1 | C11: 18 | D11: 0.1 | F11: MT | G11: 17.1 | H11: 18 | I11: 0.1 | K11: MT | L11: 17.1 | M11: 18 | N11: 0.1 | P11: MT | Q11: 17.1 | R11: 18 | S11: 0.1 | U11: MT | V11: 17.1 | W11: 18 | X11: 0.1 | Z11: MT | AA11: 16.1 | AB11: 17 | AC11: 0.15
A12: MT | B12: 18.1 | C12: 99.9 | D12: 0.25 | F12: MT | G12: 18.1 | H12: 99.9 | I12: 0.25 | K12: MT | L12: 18.1 | M12: 99.9 | N12: 0.25 | P12: MT | Q12: 18.1 | R12: 99.9 | S12: 0.25 | U12: MT | V12: 18.1 | W12: 99.9 | X12: 0.25 | Z12: MT | AA12: 17.1 | AB12: 99.9 | AC12: 0.3
A13: DMG | B13: 3.1 | C13: 4 | D13: 0.03 | F13: DMG | G13: 3.1 | H13: 4 | I13: 0.03 | K13: DMG | L13: 3.1 | M13: 4 | N13: 0.03 | P13: DMG | Q13: 3.1 | R13: 4 | S13: 0.03 | U13: DMG | V13: 3.1 | W13: 4 | X13: 0.03 | Z13: DMG | AA13: 2.1 | AB13: 3 | AC13: 0.05
A14: DMG | B14: 4.1 | C14: 5 | D14: 0.08 | F14: DMG | G14: 4.1 | H14: 5 | I14: 0.08 | K14: DMG | L14: 4.1 | M14: 5 | N14: 0.08 | P14: DMG | Q14: 4.1 | R14: 5 | S14: 0.08 | U14: DMG | V14: 4.1 | W14: 5 | X14: 0.08 | Z14: DMG | AA14: 3.1 | AB14: 4 | AC14: 0.12
A15: DMG | B15: 5.1 | C15: 6 | D15: 0.15 | F15: DMG | G15: 5.1 | H15: 6 | I15: 0.15 | K15: DMG | L15: 5.1 | M15: 6 | N15: 0.15 | P15: DMG | Q15: 5.1 | R15: 6 | S15: 0.15 | U15: DMG | V15: 5.1 | W15: 6 | X15: 0.15 | Z15: DMG | AA15: 4.1 | AB15: 5 | AC15: 0.2
A16: DMG | B16: 6.1 | C16: 99.9 | D16: 0.25 | F16: DMG | G16: 6.1 | H16: 99.9 | I16: 0.25 | K16: DMG | L16: 6.1 | M16: 99.9 | N16: 0.25 | P16: DMG | Q16: 6.1 | R16: 99.9 | S16: 0.25 | U16: DMG | V16: 6.1 | W16: 99.9 | X16: 0.25 | Z16: DMG | AA16: 5.1 | AB16: 99.9 | AC16: 0.35
A17: FM | B17: 1.1 | C17: 2 | D17: 0.02 | F17: FM | G17: 1.1 | H17: 2 | I17: 0.02 | K17: FM | L17: 1.1 | M17: 2 | N17: 0.02 | P17: FM | Q17: 1.1 | R17: 2 | S17: 0.02 | U17: FM | V17: 1.1 | W17: 2 | X17: 0.02 | Z17: FM | AA17: 0.6 | AB17: 1 | AC17: 0.03
A18: FM | B18: 2.1 | C18: 3 | D18: 0.05 | F18: FM | G18: 2.1 | H18: 3 | I18: 0.05 | K18: FM | L18: 2.1 | M18: 3 | N18: 0.05 | P18: FM | Q18: 2.1 | R18: 3 | S18: 0.05 | U18: FM | V18: 2.1 | W18: 3 | X18: 0.05 | Z18: FM | AA18: 1.1 | AB18: 2 | AC18: 0.08
A19: FM | B19: 3.1 | C19: 99.9 | D19: 0.1 | F19: FM | G19: 3.1 | H19: 99.9 | I19: 0.1 | K19: FM | L19: 3.1 | M19: 99.9 | N19: 0.1 | P19: FM | Q19: 3.1 | R19: 99.9 | S19: 0.1 | U19: FM | V19: 3.1 | W19: 99.9 | X19: 0.1 | Z19: FM | AA19: 2.1 | AB19: 99.9 | AC19: 0.2
K21: Soybean Destination Specifications
A23: Texas Soy Processors | F23: Bay Area Crushing | K23: Lone Star Soy Processing | P23: Heritage Feed & Oil | U23: Gulf Export Terminal | Z23: Coastal Export Group
A24: Factor | B24: Low | C24: High | D24: Dockage | F24: Factor | G24: Low | H24: High | I24: Dockage | K24: Factor | L24: Low | M24: High | N24: Dockage | P24: Factor | Q24: Low | R24: High | S24: Dockage | U24: Factor | V24: Low | W24: High | X24: Dockage | Z24: Factor | AA24: Low | AB24: High | AC24: Dockage
A25: MT | B25: 13.1 | C25: 14 | D25: 0.02 | F25: MT | G25: 13.1 | H25: 14 | I25: 0.02 | K25: MT | L25: 13.1 | M25: 14 | N25: 0.02 | P25: MT | Q25: 13.1 | R25: 14 | S25: 0.02 | U25: MT | V25: 12.6 | W25: 13 | X25: 0.03 | Z25: MT | AA25: 12.6 | AB25: 13 | AC25: 0.03
A26: MT | B26: 14.1 | C26: 15 | D26: 0.05 | F26: MT | G26: 14.1 | H26: 15 | I26: 0.05 | K26: MT | L26: 14.1 | M26: 15 | N26: 0.05 | P26: MT | Q26: 14.1 | R26: 15 | S26: 0.05 | U26: MT | V26: 13.1 | W26: 14 | X26: 0.08 | Z26: MT | AA26: 13.1 | AB26: 14 | AC26: 0.08
A27: MT | B27: 15.1 | C27: 16 | D27: 0.1 | F27: MT | G27: 15.1 | H27: 16 | I27: 0.1 | K27: MT | L27: 15.1 | M27: 16 | N27: 0.1 | P27: MT | Q27: 15.1 | R27: 16 | S27: 0.1 | U27: MT | V27: 14.1 | W27: 15 | X27: 0.15 | Z27: MT | AA27: 14.1 | AB27: 15 | AC27: 0.15
A28: MT | B28: 16.1 | C28: 99.9 | D28: 0.25 | F28: MT | G28: 16.1 | H28: 99.9 | I28: 0.25 | K28: MT | L28: 16.1 | M28: 99.9 | N28: 0.25 | P28: MT | Q28: 16.1 | R28: 99.9 | S28: 0.25 | U28: MT | V28: 15.1 | W28: 99.9 | X28: 0.3 | Z28: MT | AA28: 15.1 | AB28: 99.9 | AC28: 0.3
A29: DMG | B29: 3.1 | C29: 4 | D29: 0.03 | F29: DMG | G29: 3.1 | H29: 4 | I29: 0.03 | K29: DMG | L29: 3.1 | M29: 4 | N29: 0.03 | P29: DMG | Q29: 3.1 | R29: 4 | S29: 0.03 | U29: DMG | V29: 2.1 | W29: 3 | X29: 0.05 | Z29: DMG | AA29: 2.1 | AB29: 3 | AC29: 0.05
A30: DMG | B30: 4.1 | C30: 5 | D30: 0.08 | F30: DMG | G30: 4.1 | H30: 5 | I30: 0.08 | K30: DMG | L30: 4.1 | M30: 5 | N30: 0.08 | P30: DMG | Q30: 4.1 | R30: 5 | S30: 0.08 | U30: DMG | V30: 3.1 | W30: 4 | X30: 0.12 | Z30: DMG | AA30: 3.1 | AB30: 4 | AC30: 0.12
A31: DMG | B31: 5.1 | C31: 6 | D31: 0.15 | F31: DMG | G31: 5.1 | H31: 6 | I31: 0.15 | K31: DMG | L31: 5.1 | M31: 6 | N31: 0.15 | P31: DMG | Q31: 5.1 | R31: 6 | S31: 0.15 | U31: DMG | V31: 4.1 | W31: 5 | X31: 0.2 | Z31: DMG | AA31: 4.1 | AB31: 5 | AC31: 0.2
A32: DMG | B32: 6.1 | C32: 99.9 | D32: 0.25 | F32: DMG | G32: 6.1 | H32: 99.9 | I32: 0.25 | K32: DMG | L32: 6.1 | M32: 99.9 | N32: 0.25 | P32: DMG | Q32: 6.1 | R32: 99.9 | S32: 0.25 | U32: DMG | V32: 5.1 | W32: 99.9 | X32: 0.35 | Z32: DMG | AA32: 5.1 | AB32: 99.9 | AC32: 0.35
A33: FM | B33: 1.1 | C33: 2 | D33: 0.02 | F33: FM | G33: 1.1 | H33: 2 | I33: 0.02 | K33: FM | L33: 1.1 | M33: 2 | N33: 0.02 | P33: FM | Q33: 1.1 | R33: 2 | S33: 0.02 | U33: FM | V33: 0.6 | W33: 1 | X33: 0.03 | Z33: FM | AA33: 0.6 | AB33: 1 | AC33: 0.03
A34: FM | B34: 2.1 | C34: 3 | D34: 0.05 | F34: FM | G34: 2.1 | H34: 3 | I34: 0.05 | K34: FM | L34: 2.1 | M34: 3 | N34: 0.05 | P34: FM | Q34: 2.1 | R34: 3 | S34: 0.05 | U34: FM | V34: 1.1 | W34: 2 | X34: 0.08 | Z34: FM | AA34: 1.1 | AB34: 2 | AC34: 0.08
A35: FM | B35: 3.1 | C35: 99.9 | D35: 0.1 | F35: FM | G35: 3.1 | H35: 99.9 | I35: 0.1 | K35: FM | L35: 3.1 | M35: 99.9 | N35: 0.1 | P35: FM | Q35: 3.1 | R35: 99.9 | S35: 0.1 | U35: FM | V35: 2.1 | W35: 99.9 | X35: 0.2 | Z35: FM | AA35: 2.1 | AB35: 99.9 | AC35: 0.2
GG314: Buyer | GH314: Commodity | GI314: Factor | GJ314: Low | GK314: High | GL314: Dockage
GG315: Bayport Ethanol | GH315: Corn | GI315: MT | GJ315: 15.1 | GK315: 16 | GL315: 0.02
GG316: Bayport Ethanol | GH316: Corn | GI316: MT | GJ316: 16.1 | GK316: 17 | GL316: 0.05
GG317: Bayport Ethanol | GH317: Corn | GI317: MT | GJ317: 17.1 | GK317: 18 | GL317: 0.1
GG318: Bayport Ethanol | GH318: Corn | GI318: MT | GJ318: 18.1 | GK318: 99.9 | GL318: 0.25
GG319: Bayport Ethanol | GH319: Corn | GI319: DMG | GJ319: 3.1 | GK319: 4 | GL319: 0.03
GG320: Bayport Ethanol | GH320: Corn | GI320: DMG | GJ320: 4.1 | GK320: 5 | GL320: 0.08
GG321: Bayport Ethanol | GH321: Corn | GI321: DMG | GJ321: 5.1 | GK321: 6 | GL321: 0.15
GG322: Bayport Ethanol | GH322: Corn | GI322: DMG | GJ322: 6.1 | GK322: 99.9 | GL322: 0.25
GG323: Bayport Ethanol | GH323: Corn | GI323: FM | GJ323: 1.1 | GK323: 2 | GL323: 0.02
GG324: Bayport Ethanol | GH324: Corn | GI324: FM | GJ324: 2.1 | GK324: 3 | GL324: 0.05
...

Sheet Position
C3: Open Sales Position by Location | I3: Futures Hedge Position
C5: Commodity | D5: Location | E5: Contracted | F5: Delivered | G5: Remaining | I5: Futures Code | J5: Open Bushels | K5: Futures Hedged | L5: Net Position
C6: Corn | D6: Pasadena | E6: =SUMIFS('Sale Contracts'!$L:$L,'Sale Contracts'!$C:$C,$C6,'Sale Contracts'!$D:$D,$D6&", TX") -> 19000 | F6: =SUMIFS('Sale Contracts'!$M:$M,'Sale Contracts'!$C:$C,$C6,'Sale Contracts'!$D:$D,$D6&", TX") -> 2600.7143 | G6: =SUMIFS('Sale Contracts'!$N:$N,'Sale Contracts'!$C:$C,$C6,'Sale Contracts'!$D:$D,$D6&", TX") -> 16399.286 | I6: CH26 | J6: =SUMIFS('Purchase Contracts'!$L:$L,'Purchase Contracts'!$F:$F,I6) -> 24091 | K6: 20000 | L6: =J6-K6 -> 4091
C7: Corn | D7: Mont Belvieu | E7: =SUMIFS('Sale Contracts'!$L:$L,'Sale Contracts'!$C:$C,$C7,'Sale Contracts'!$D:$D,$D7&", TX") -> 9000 | F7: =SUMIFS('Sale Contracts'!$M:$M,'Sale Contracts'!$C:$C,$C7,'Sale Contracts'!$D:$D,$D7&", TX") -> 878.57143 | G7: =SUMIFS('Sale Contracts'!$N:$N,'Sale Contracts'!$C:$C,$C7,'Sale Contracts'!$D:$D,$D7&", TX") -> 8121.4286 | I7: CN26 | J7: =SUMIFS('Purchase Contracts'!$L:$L,'Purchase Contracts'!$F:$F,I7) -> 34168 | K7: 30000 | L7: =J7-K7 -> 4168
C8: Corn | D8: Humble | E8: =SUMIFS('Sale Contracts'!$L:$L,'Sale Contracts'!$C:$C,$C8,'Sale Contracts'!$D:$D,$D8&", TX") -> 12000 | F8: =SUMIFS('Sale Contracts'!$M:$M,'Sale Contracts'!$C:$C,$C8,'Sale Contracts'!$D:$D,$D8&", TX") -> 867.5 | G8: =SUMIFS('Sale Contracts'!$N:$N,'Sale Contracts'!$C:$C,$C8,'Sale Contracts'!$D:$D,$D8&", TX") -> 11132.5 | I8: CU26 | J8: =SUMIFS('Purchase Contracts'!$L:$L,'Purchase Contracts'!$F:$F,I8) -> 12000 | K8: 10000 | L8: =J8-K8 -> 2000
C9: Corn | D9: Porter | E9: =SUMIFS('Sale Contracts'!$L:$L,'Sale Contracts'!$C:$C,$C9,'Sale Contracts'!$D:$D,$D9&", TX") -> 10000 | F9: =SUMIFS('Sale Contracts'!$M:$M,'Sale Contracts'!$C:$C,$C9,'Sale Contracts'!$D:$D,$D9&", TX") -> 875.71429 | G9: =SUMIFS('Sale Contracts'!$N:$N,'Sale Contracts'!$C:$C,$C9,'Sale Contracts'!$D:$D,$D9&", TX") -> 9124.2857 | I9: CZ26 | J9: =SUMIFS('Purchase Contracts'!$L:$L,'Purchase Contracts'!$F:$F,I9) -> 40409 | K9: 35000 | L9: =J9-K9 -> 5409
C10: Corn | D10: Sugarland | E10: =SUMIFS('Sale Contracts'!$L:$L,'Sale Contracts'!$C:$C,$C10,'Sale Contracts'!$D:$D,$D10&", TX") -> 0 | F10: =SUMIFS('Sale Contracts'!$M:$M,'Sale Contracts'!$C:$C,$C10,'Sale Contracts'!$D:$D,$D10&", TX") -> 0 | G10: =SUMIFS('Sale Contracts'!$N:$N,'Sale Contracts'!$C:$C,$C10,'Sale Contracts'!$D:$D,$D10&", TX") -> 0 | I10: SQ26 | J10: =SUMIFS('Purchase Contracts'!$L:$L,'Purchase Contracts'!$F:$F,I10) -> 4000 | K10: 4000 | L10: =J10-K10 -> 0
C11: Soybeans | D11: Mont Belvieu | E11: =SUMIFS('Sale Contracts'!$L:$L,'Sale Contracts'!$C:$C,$C11,'Sale Contracts'!$D:$D,$D11&", TX") -> 6000 | F11: =SUMIFS('Sale Contracts'!$M:$M,'Sale Contracts'!$C:$C,$C11,'Sale Contracts'!$D:$D,$D11&", TX") -> 816.66667 | G11: =SUMIFS('Sale Contracts'!$N:$N,'Sale Contracts'!$C:$C,$C11,'Sale Contracts'!$D:$D,$D11&", TX") -> 5183.3333 | I11: SU26 | J11: =SUMIFS('Purchase Contracts'!$L:$L,'Purchase Contracts'!$F:$F,I11) -> 1670 | K11: 0 | L11: =J11-K11 -> 1670
C12: Soybeans | D12: Galveston | E12: =SUMIFS('Sale Contracts'!$L:$L,'Sale Contracts'!$C:$C,$C12,'Sale Contracts'!$D:$D,$D12&", TX") -> 22000 | F12: =SUMIFS('Sale Contracts'!$M:$M,'Sale Contracts'!$C:$C,$C12,'Sale Contracts'!$D:$D,$D12&", TX") -> 830 | G12: =SUMIFS('Sale Contracts'!$N:$N,'Sale Contracts'!$C:$C,$C12,'Sale Contracts'!$D:$D,$D12&", TX") -> 21170 | I12: SX26 | J12: =SUMIFS('Purchase Contracts'!$L:$L,'Purchase Contracts'!$F:$F,I12) -> 32784 | K12: 40000 | L12: =J12-K12 -> -7216
C13: Soybeans | D13: Porter | E13: =SUMIFS('Sale Contracts'!$L:$L,'Sale Contracts'!$C:$C,$C13,'Sale Contracts'!$D:$D,$D13&", TX") -> 7000 | F13: =SUMIFS('Sale Contracts'!$M:$M,'Sale Contracts'!$C:$C,$C13,'Sale Contracts'!$D:$D,$D13&", TX") -> 823.33333 | G13: =SUMIFS('Sale Contracts'!$N:$N,'Sale Contracts'!$C:$C,$C13,'Sale Contracts'!$D:$D,$D13&", TX") -> 6176.6667
C14: Soybeans | D14: Sugarland | E14: =SUMIFS('Sale Contracts'!$L:$L,'Sale Contracts'!$C:$C,$C14,'Sale Contracts'!$D:$D,$D14&", TX") -> 0 | F14: =SUMIFS('Sale Contracts'!$M:$M,'Sale Contracts'!$C:$C,$C14,'Sale Contracts'!$D:$D,$D14&", TX") -> 0 | G14: =SUMIFS('Sale Contracts'!$N:$N,'Sale Contracts'!$C:$C,$C14,'Sale Contracts'!$D:$D,$D14&", TX") -> 0 | I14: Sales Position Summary
C15: Soybeans | D15: Pasadena | E15: =SUMIFS('Sale Contracts'!$L:$L,'Sale Contracts'!$C:$C,$C15,'Sale Contracts'!$D:$D,$D15&", TX") -> 8000 | F15: =SUMIFS('Sale Contracts'!$M:$M,'Sale Contracts'!$C:$C,$C15,'Sale Contracts'!$D:$D,$D15&", TX") -> 0 | G15: =SUMIFS('Sale Contracts'!$N:$N,'Sale Contracts'!$C:$C,$C15,'Sale Contracts'!$D:$D,$D15&", TX") -> 8000
I16: Total Open Sales Bushels | K16: =SUM(G6:G15) -> 85307.5
C17: Positioning Alert | I17: Largest Destination Exposure | K17: =INDEX(D6:D15,MATCH(MAX(G6:G15),G6:G15,0)) -> Galveston
C18: =IF(MAX(G6:G15)>20000,"HIGH DESTINATION EXPOSURE","NORMAL") -> HIGH DESTINATION EXPOSURE | I18: Open Corn Sales | K18: =SUMIFS(G6:G15,C6:C15,"Corn") -> 44777.5
I19: Open Soybean Sales | K19: =SUMIFS(G6:G15,C6:C15,"Soybeans") -> 40530

Sheet Dashboard
A1: Location | B1: Remaining Bu | G1: Grain Merchandising Dashboard
A2: Houston | B2: 53553 | F2: Futures Code
A3: Pasadena | B3: 15151
A4: Mont Belvieu | B4: 13292 | O4: Open Bushels | P4: Futures Hedged
